<?xml version="1.0" ?>
<!-- =================================================================================== -->
<!-- |    This document was autogenerated by xacro from wam7_bhand.urdf.xacro          | -->
<!-- |    EDITING THIS FILE BY HAND IS NOT RECOMMENDED                                 | -->
<!-- =================================================================================== -->
<robot name="wam" xmlns:controller="http://playerstage.sourceforge.net/gazebo/xmlschema/#controller" xmlns:xacro="http://ros.org/wiki/xacro">
  <!-- Includea all the WAM stuff -->
  <material name="WAMGrey">
    <color rgba="0.7 0.7 0.7 1.0"/>
  </material>
  <!-- Root link is in the world frame-->
  <link name="rack1">
    <visual>
      <geometry>
        <box size="1.831975 0.0889 0.0492125"/>
      </geometry>
    </visual>
  </link>
  <link name="rack2">
    <visual>
      <geometry>
        <box size="0.6334125 0.0889 0.0492125"/>
      </geometry>
      <origin rpy="0 0 1.57075" xyz="0 0 0"/>
    </visual>
  </link>
  <link name="rack3">
    <visual>
      <geometry>
        <box size="0.6334125 0.0889 0.0492125"/>
      </geometry>
      <origin rpy="0 0 1.57075" xyz="0 0 0"/>
    </visual>
  </link>
  <link name="rack4">
    <visual>
      <geometry>
        <box size="1.2446 0.0889 0.0492125"/>
      </geometry>
      <origin rpy="0 0 1.57075" xyz="0 0 0"/>
    </visual>
  </link>
  <link name="rack5">
    <visual>
      <geometry>
        <box size="1.905 0.0889 0.0889"/>
      </geometry>
      <origin rpy="0 1.57075 0" xyz="0 0 0.9525"/>
    </visual>
  </link>
  <link name="rack6">
    <visual>
      <geometry>
        <box size="1.025525 0.3175 0.32385"/>
      </geometry>
      <origin rpy="0 0 0" xyz="0 0 0"/>
    </visual>
  </link>
  <link name="left_wam_rack"/>
  <link name="right_wam_rack"/>
  <joint name="rack1_to_rack2" type="fixed">
    <parent link="rack1"/>
    <child link="rack2"/>
    <origin xyz="0.8778875 0 -0.0492125"/>
  </joint>
  <joint name="rack1_to_rack3" type="fixed">
    <parent link="rack1"/>
    <child link="rack3"/>
    <origin xyz="-0.8778875 0 -0.0492125"/>
  </joint>
  <joint name="rack1_to_rack4" type="fixed">
    <parent link="rack1"/>
    <child link="rack4"/>
    <origin xyz="0 0.2794 -0.0492125"/>
  </joint>
  <joint name="rack1_to_rack5" type="fixed">
    <parent link="rack1"/>
    <child link="rack5"/>
    <origin xyz="0 0 0.0492125"/>
  </joint>
  <joint name="rack5_to_rack6" type="fixed">
    <parent link="rack5"/>
    <child link="rack6"/>
    <origin xyz="0 0 1.2239625"/>
  </joint>
  <joint name="rack6_to_leftwam" type="fixed">
    <parent link="rack6"/>
    <child link="left_wam_rack"/>
    <origin xyz="0.2936875 0.15875 0"/>
  </joint>
  <joint name="rack6_to_righttwam" type="fixed">
    <parent link="rack6"/>
    <child link="right_wam_rack"/>
    <origin xyz="-0.2936875 0.15875 0"/>
  </joint>
  <!-- 7-DOF Wam -->
  <!-- right wam -->
  <!-- <xacro:wam_right prefix="right_wam" parent_link="right_wam_rack" xyz="0.0 0.0 0" rpy="-1.57075 0 0" /> -->
  <!-- <xacro:wam_wrist_right prefix="right_wam"/> -->
  <!-- <xacro:bhand prefix="right_wam/bhand" parent_link="right_wam/wrist_palm_link" xyz="0 0 0.06" rpy="0 0 0"/> -->
  <!-- left wam -->
  <joint name="left_wam/wam_fixed_joint" type="fixed">
    <parent link="left_wam_rack"/>
    <child link="left_wam/base_link"/>
    <origin rpy="-1.57075 -3.14159265359 0" xyz="0.0 0.0 0"/>
  </joint>
  <link name="left_wam/base_link">
    <inertial>
      <origin xyz="0 0 0"/>
      <mass value="1"/>
      <inertia ixx="0.1" ixy="0" ixz="0" iyy="0.1" iyz="0" izz="0.1"/>
    </inertial>
    <visual>
      <material name="WAMGrey">
        <color rgba="0.7 0.7 0.7 0.0"/>
      </material>
      <geometry>
        <mesh filename="package://barrett_model/models/sw_meshes/base_link_convex.dae"/>
      </geometry>
    </visual>
    <collision>
      <geometry>
        <mesh filename="package://barrett_model/models/sw_meshes/base_link_convex.dae"/>
      </geometry>
    </collision>
  </link>
  <joint name="left_wam/base_yaw_joint" type="revolute">
    <parent link="left_wam/base_link"/>
    <child link="left_wam/shoulder_yaw_link"/>
    <origin rpy="0 0 0" xyz="0 0 0.346"/>
    <axis xyz="0 0 1"/>
    <limit effort="60" lower="-2.6" upper="2.6" velocity="2.0"/>
    <dynamics damping="1.98" friction="0"/>
  </joint>
  <gazebo reference="left_wam/base_yaw_joint">
    <provideFeedback>true</provideFeedback>
    <implicitSpringDamper>true</implicitSpringDamper>
  </gazebo>
  <link name="left_wam/shoulder_yaw_link">
    <inertial>
      <origin xyz="-.00443422 -.00066489 -0.1289039 "/>
      <mass value="5.0"/>
      <inertia ixx=".13488033" ixy="-0.00012485" ixz="0.00213041" iyy=".09046330" iyz="-.00068555" izz=".11328369"/>
    </inertial>
    <visual>
      <material name="WAMGrey">
        <color rgba="0.7 0.7 0.7 1.0"/>
      </material>
      <geometry>
        <mesh filename="package://barrett_model/models/sw_meshes/shoulder_link_convex_decomposition.dae"/>
      </geometry>
    </visual>
    <collision>
      <geometry>
        <mesh filename="package://barrett_model/models/sw_meshes/shoulder_link_convex_decomposition.dae"/>
      </geometry>
    </collision>
  </link>
  <joint name="left_wam/shoulder_pitch_joint" type="revolute">
    <parent link="left_wam/shoulder_yaw_link"/>
    <child link="left_wam/shoulder_pitch_link"/>
    <origin rpy="0 0 0" xyz="0 0 0"/>
    <axis xyz="0 1 0"/>
    <limit effort="60" lower="-2.0" upper="2.0" velocity="2.0"/>
    <dynamics damping="0.55" friction="0"/>
  </joint>
  <gazebo reference="left_wam/shoulder_pitch_joint">
    <provideFeedback>true</provideFeedback>
    <implicitSpringDamper>true</implicitSpringDamper>
  </gazebo>
  <link name="left_wam/shoulder_pitch_link">
    <visual>
      <material name="WAMGrey">
        <color rgba="0.7 0.7 0.7 1.0"/>
      </material>
      <geometry>
        <mesh filename="package://barrett_model/models/sw_meshes/shoulder_pitch_link_convex.dae"/>
      </geometry>
    </visual>
    <inertial>
      <origin xyz="-.00236981 -.01542114 .03105614 "/>
      <mass value="3.87493756"/>
      <inertia ixx="0.02140958" ixy="-0.00002461" ixz="0.00027172" iyy="0.015589060" iyz="0.0018192" izz="0.01377875"/>
    </inertial>
    <collision>
      <geometry>
        <mesh filename="package://barrett_model/models/sw_meshes/shoulder_pitch_link_convex.dae"/>
      </geometry>
    </collision>
  </link>
  <joint name="left_wam/shoulder_yaw_joint" type="revolute">
    <parent link="left_wam/shoulder_pitch_link"/>
    <child link="left_wam/upper_arm_link"/>
    <origin rpy="0 0 0" xyz="0 0 0"/>
    <axis xyz="0 0 1"/>
    <limit effort="45" lower="-2.8" upper="2.8" velocity="2.0"/>
    <dynamics damping="1.65" friction="0"/>
  </joint>
  <gazebo reference="left_wam/shoulder_yaw_joint">
    <provideFeedback>true</provideFeedback>
    <implicitSpringDamper>true</implicitSpringDamper>
  </gazebo>
  <link name="left_wam/upper_arm_link">
    <inertial>
      <origin xyz="0.00683258580000000 0.000033090000000 0.392492300000000"/>
      <mass value="2.20228141"/>
      <inertia ixx=".05911077" ixy="-0.00000738" ixz="-0.00249612" iyy="0.05927043" iyz="0.00001767" izz="0.0032455"/>
    </inertial>
    <visual>
      <material name="WAMGrey">
        <color rgba="0.7 0.7 0.7 1.0"/>
      </material>
      <geometry>
        <mesh filename="package://barrett_model/models/sw_meshes/upper_arm_link_convex_decomposition.dae"/>
      </geometry>
    </visual>
    <collision>
      <geometry>
        <mesh filename="package://barrett_model/models/sw_meshes/upper_arm_link_convex_decomposition.dae"/>
      </geometry>
    </collision>
  </link>
  <joint name="left_wam/elbow_pitch_joint" type="revolute">
    <parent link="left_wam/upper_arm_link"/>
    <child link="left_wam/forearm_link"/>
    <origin rpy="-1.57079632679 0 0" xyz="0.045 0 0.55"/>
    <axis xyz="0 0 1"/>
    <limit effort="30" lower="-0.9" upper="3.14159265359" velocity="2.00"/>
    <dynamics damping="0.88" friction="0"/>
  </joint>
  <gazebo reference="left_wam/elbow_pitch_joint">
    <provideFeedback>true</provideFeedback>
    <implicitSpringDamper>true</implicitSpringDamper>
  </gazebo>
  <link name="left_wam/forearm_link">
    <inertial>
      <mass value="0.50016804"/>
      <origin rpy="0 0 0" xyz="-0.04001488 -.14271662 -.00022942 "/>
      <inertia ixx="0.01491672" ixy="0.001506040000000" ixz="0.000017410000000" iyy="0.002944630000000" iyz="0.000021090000000" izz="0.014829880000000"/>
    </inertial>
    <visual>
      <material name="WAMGrey">
        <color rgba="0.7 0.7 0.7 1.0"/>
      </material>
      <geometry>
        <mesh filename="package://barrett_model/models/sw_meshes/elbow_link_convex.dae"/>
      </geometry>
    </visual>
    <collision>
      <geometry>
        <mesh filename="package://barrett_model/models/sw_meshes/elbow_link_convex.dae"/>
      </geometry>
    </collision>
    <visual>
      <material name="WAMGrey">
        <color rgba="0.7 0.7 0.7 1.0"/>
      </material>
      <origin rpy="1.57079632679 0 0" xyz="-0.045 -0.0730 0"/>
      <geometry>
        <mesh filename="package://barrett_model/models/sw_meshes/forearm_link_convex_decomposition.dae"/>
      </geometry>
    </visual>
    <collision>
      <origin rpy="1.57079632679 0 0" xyz="-0.045 -0.0730 0"/>
      <geometry>
        <mesh filename="package://barrett_model/models/sw_meshes/forearm_link_convex_decomposition.dae"/>
      </geometry>
    </collision>
  </link>
  <joint name="left_wam/wrist_yaw_joint" type="revolute">
    <parent link="left_wam/forearm_link"/>
    <child link="left_wam/wrist_yaw_link"/>
    <origin rpy="1.57079632679 0 0" xyz="-0.045 -0.3 0"/>
    <axis xyz="0 0 1"/>
    <limit effort="10" lower="-4.76" upper="1.24" velocity="2.0"/>
    <dynamics damping="0.55" friction="0"/>
  </joint>
  <gazebo reference="left_wam/wrist_yaw_joint">
    <provideFeedback>true</provideFeedback>
    <implicitSpringDamper>true</implicitSpringDamper>
  </gazebo>
  <link name="left_wam/wrist_yaw_link">
    <inertial>
      <origin xyz="0.00008921 0.00435824 -0.00511217 "/>
      <mass value="1.05376019"/>
      <inertia ixx="0.00005029" ixy="0.00000020" ixz="0.00007582" iyy="0.00007582" iyz="-0.00000359" izz="0.00006270"/>
    </inertial>
    <visual>
      <material name="WAMGrey">
        <color rgba="0.7 0.7 0.7 1.0"/>
      </material>
      <origin rpy="0 0 0" xyz="0 0 0"/>
      <geometry>
        <mesh filename="package://barrett_model/models/sw_meshes/wrist_yaw_link_convex_decomposition.dae"/>
      </geometry>
    </visual>
    <collision>
      <origin rpy="0 0 0" xyz="0 0 0"/>
      <geometry>
        <mesh filename="package://barrett_model/models/sw_meshes/wrist_yaw_link_convex_decomposition.dae"/>
      </geometry>
    </collision>
  </link>
  <joint name="left_wam/wrist_pitch_joint" type="revolute">
    <parent link="left_wam/wrist_yaw_link"/>
    <child link="left_wam/wrist_pitch_link"/>
    <origin rpy="-1.57079632679 0 0" xyz="0 0 0"/>
    <axis xyz="0 0 1"/>
    <limit effort="10" lower="-1.6" upper="1.6" velocity="2.00"/>
    <dynamics damping="0.11" friction="0"/>
  </joint>
  <gazebo reference="left_wam/wrist_pitch_joint">
    <provideFeedback>true</provideFeedback>
    <implicitSpringDamper>true</implicitSpringDamper>
  </gazebo>
  <link name="left_wam/wrist_pitch_link">
    <inertial>
      <origin rpy="0 0 0" xyz="-0.00012262 -0.02468336 -0.01703194 "/>
      <mass value="0.51797364"/>
      <inertia ixx="0.00055516" ixy="0.00000061" ixz="-0.00000074" iyy="0.00024367" iyz="-0.00004590" izz="0.00045358"/>
    </inertial>
    <visual>
      <material name="WAMGrey">
        <color rgba="0.7 0.7 0.7 1.0"/>
      </material>
      <geometry>
        <mesh filename="package://barrett_model/models/sw_meshes/wrist_pitch_link_convex_decomposition.dae"/>
      </geometry>
    </visual>
    <collision>
      <geometry>
        <mesh filename="package://barrett_model/models/sw_meshes/wrist_pitch_link_convex_decomposition.dae"/>
      </geometry>
    </collision>
  </link>
  <joint name="left_wam/palm_yaw_joint" type="revolute">
    <parent link="left_wam/wrist_pitch_link"/>
    <child link="left_wam/wrist_palm_link"/>
    <origin rpy="1.57079632679 1.57079632679 0" xyz="0 0 0"/>
    <axis xyz="0 0 1"/>
    <limit effort="10" lower="-3.0" upper="3.0" velocity="2.00"/>
    <!-- 2.95 is a limit taken in from 3 due to saftey and differences between arms. -->
    <dynamics damping="0.11" friction="0"/>
  </joint>
  <gazebo reference="left_wam/palm_yaw_joint">
    <provideFeedback>true</provideFeedback>
    <implicitSpringDamper>true</implicitSpringDamper>
  </gazebo>
  <link name="left_wam/wrist_palm_link">
    <inertial>
      <origin rpy="0 0 0" xyz="0.0 0.0 0.055"/>
      <mass value="0.08286134"/>
      <inertia ixx="0.00010859" ixy="0.00000000" ixz="-0.00000000" iyy="0.00020683" iyz="-0.0000000" izz="0.00010851"/>
    </inertial>
    <visual>
      <material name="WAMGrey">
        <color rgba="0.7 0.7 0.7 1.0"/>
      </material>
      <origin rpy="0 0 0" xyz="0 0 0"/>
      <geometry>
        <mesh filename="package://barrett_model/models/sw_meshes/wrist_palm_link_convex.dae"/>
      </geometry>
    </visual>
    <collision>
      <origin rpy="0 0 0" xyz="0 0 0"/>
      <geometry>
        <mesh filename="package://barrett_model/models/sw_meshes/wrist_palm_link_convex.dae"/>
      </geometry>
    </collision>
  </link>
  <!-- <xacro:bhand prefix="left_wam/bhand" parent_link="left_wam/wrist_palm_link" xyz="0 0 0.06" rpy="0 0 0"/> -->
</robot>
